Exception on /upload [GET]
Traceback (most recent call last):
  File "/home/bhanu/myproject/ENV/local/lib/python2.7/site-packages/flask/app.py", line 1817, in wsgi_app
    response = self.full_dispatch_request()
  File "/home/bhanu/myproject/ENV/local/lib/python2.7/site-packages/flask/app.py", line 1477, in full_dispatch_request
    rv = self.handle_user_exception(e)
  File "/home/bhanu/myproject/ENV/local/lib/python2.7/site-packages/flask/app.py", line 1381, in handle_user_exception
    reraise(exc_type, exc_value, tb)
  File "/home/bhanu/myproject/ENV/local/lib/python2.7/site-packages/flask/app.py", line 1475, in full_dispatch_request
    rv = self.dispatch_request()
  File "/home/bhanu/myproject/ENV/local/lib/python2.7/site-packages/flask/app.py", line 1461, in dispatch_request
    return self.view_functions[rule.endpoint](**req.view_args)
  File "mouchak/server.py", line 332, in upload
    uploaded_files = os.listdir(app.config.get('FILE_UPLOAD_FOLDER'))
TypeError: coercing to Unicode: need string or buffer, NoneType found
Exception on /analytics [POST]
Traceback (most recent call last):
  File "/home/bhanu/myproject/ENV/local/lib/python2.7/site-packages/flask/app.py", line 1817, in wsgi_app
    response = self.full_dispatch_request()
  File "/home/bhanu/myproject/ENV/local/lib/python2.7/site-packages/flask/app.py", line 1477, in full_dispatch_request
    rv = self.handle_user_exception(e)
  File "/home/bhanu/myproject/ENV/local/lib/python2.7/site-packages/flask/app.py", line 1381, in handle_user_exception
    reraise(exc_type, exc_value, tb)
  File "/home/bhanu/myproject/ENV/local/lib/python2.7/site-packages/flask/app.py", line 1475, in full_dispatch_request
    rv = self.dispatch_request()
  File "/home/bhanu/myproject/ENV/local/lib/python2.7/site-packages/flask/app.py", line 1461, in dispatch_request
    return self.view_functions[rule.endpoint](**req.view_args)
  File "mouchak/server.py", line 354, in analytics
    response = flask.make_response()
NameError: global name 'flask' is not defined
Exception on /analytics [POST]
Traceback (most recent call last):
  File "/home/bhanu/myproject/ENV/local/lib/python2.7/site-packages/flask/app.py", line 1817, in wsgi_app
    response = self.full_dispatch_request()
  File "/home/bhanu/myproject/ENV/local/lib/python2.7/site-packages/flask/app.py", line 1477, in full_dispatch_request
    rv = self.handle_user_exception(e)
  File "/home/bhanu/myproject/ENV/local/lib/python2.7/site-packages/flask/app.py", line 1381, in handle_user_exception
    reraise(exc_type, exc_value, tb)
  File "/home/bhanu/myproject/ENV/local/lib/python2.7/site-packages/flask/app.py", line 1475, in full_dispatch_request
    rv = self.dispatch_request()
  File "/home/bhanu/myproject/ENV/local/lib/python2.7/site-packages/flask/app.py", line 1461, in dispatch_request
    return self.view_functions[rule.endpoint](**req.view_args)
  File "mouchak/server.py", line 354, in analytics
    response = flask.make_response()
NameError: global name 'flask' is not defined
